Workbook
Name NativeTimeline_Order_Date: #N/A
Name Slicer_Loyalty_Card: #N/A
Name Slicer_Roast_Type_Name: #N/A
Name Slicer_Size: #N/A

Sheet Dashboard

Sheet TotalSales
A3: Sum of Sales | C3: Coffee Type Name
A4: Years (Order Date) | B4: Months (Order Date) | C4: Arabica | D4: Excelsa | E4: Liberica | F4: Robusta | G4: Grand Total
A5: 2019 | B5: Jan | C5: 186.855 | D5: 305.97 | E5: 213.16 | F5: 123 | G5: 828.985
B6: Feb | C6: 251.965 | D6: 129.46 | E6: 434.04 | F6: 171.94 | G6: 987.405
B7: Mar | C7: 224.945 | D7: 349.12 | E7: 321.04 | F7: 126.035 | G7: 1021.14
B8: Apr | C8: 307.12 | D8: 681.075 | E8: 533.705 | F8: 158.85 | G8: 1680.75
B9: May | C9: 53.665 | D9: 83.025 | E9: 193.835 | F9: 68.04 | G9: 398.565
B10: Jun | C10: 163.02 | D10: 678.36 | E10: 171.045 | F10: 372.255 | G10: 1384.68
B11: Jul | C11: 345.02 | D11: 273.87 | E11: 184.13 | F11: 201.115 | G11: 1004.135
B12: Aug | C12: 334.89 | D12: 70.95 | E12: 134.23 | F12: 166.275 | G12: 706.345
B13: Sep | C13: 178.71 | D13: 166.1 | E13: 439.31 | F13: 492.9 | G13: 1277.02
B14: Oct | C14: 301.985 | D14: 153.765 | E14: 215.555 | F14: 213.665 | G14: 884.97
B15: Nov | C15: 312.835 | D15: 63.25 | E15: 350.895 | F15: 96.405 | G15: 823.385
B16: Dec | C16: 265.62 | D16: 526.515 | E16: 187.06 | F16: 210.59 | G16: 1189.785
A17: 2020 | B17: Jan | C17: 47.25 | D17: 65.805 | E17: 274.675 | F17: 179.22 | G17: 566.95
B18: Feb | C18: 745.45 | D18: 428.885 | E18: 194.175 | F18: 429.83 | G18: 1798.34
B19: Mar | C19: 130.47 | D19: 271.485 | E19: 281.205 | F19: 231.63 | G19: 914.79
B20: Apr | C20: 27 | D20: 347.26 | E20: 147.51 | F20: 240.04 | G20: 761.81
B21: May | C21: 255.115 | D21: 541.73 | E21: 83.43 | F21: 59.08 | G21: 939.355
B22: Jun | C22: 584.79 | D22: 357.43 | E22: 355.34 | F22: 140.88 | G22: 1438.44
B23: Jul | C23: 430.62 | D23: 227.425 | E23: 236.315 | F23: 414.585 | G23: 1308.945
B24: Aug | C24: 22.5 | D24: 77.72 | E24: 60.5 | F24: 139.68 | G24: 300.4
B25: Sep | C25: 126.15 | D25: 195.11 | E25: 89.13 | F25: 302.66 | G25: 713.05
B26: Oct | C26: 376.03 | D26: 523.24 | E26: 440.965 | F26: 174.47 | G26: 1514.705
B27: Nov | C27: 515.18 | D27: 142.56 | E27: 347.04 | F27: 104.085 | G27: 1108.865
B28: Dec | C28: 95.86 | D28: 484.76 | E28: 94.17 | F28: 77.105 | G28: 751.895
A29: 2021 | B29: Jan | C29: 258.345 | D29: 139.625 | E29: 279.52 | F29: 160.195 | G29: 837.685
B30: Feb | C30: 342.2 | D30: 284.25 | E30: 251.83 | F30: 80.55 | G30: 958.83
B31: Mar | C31: 418.305 | D31: 468.125 | E31: 405.055 | F31: 253.155 | G31: 1544.64
B32: Apr | C32: 102.33 | D32: 242.14 | E32: 554.875 | F32: 106.24 | G32: 1005.585
B33: May | C33: 234.72 | D33: 133.08 | E33: 267.2 | F33: 272.69 | G33: 907.69
B34: Jun | C34: 430.39 | D34: 136.205 | E34: 209.6 | F34: 88.335 | G34: 864.53
B35: Jul | C35: 109.005 | D35: 393.575 | E35: 61.035 | F35: 199.49 | G35: 763.105
B36: Aug | C36: 287.525 | D36: 288.67 | E36: 125.58 | F36: 374.135 | G36: 1075.91
B37: Sep | C37: 840.93 | D37: 409.875 | E37: 171.33 | F37: 221.44 | G37: 1643.575
B38: Oct | C38: 299.07 | D38: 260.325 | E38: 584.64 | F38: 256.365 | G38: 1400.4
B39: Nov | C39: 323.325 | D39: 565.57 | E39: 537.81 | F39: 189.475 | G39: 1616.18
B40: Dec | C40: 399.485 | D40: 148.2 | E40: 388.22 | F40: 212.075 | G40: 1147.98
A41: 2022 | B41: Jan | C41: 112.695 | D41: 166.32 | E41: 843.715 | F41: 146.685 | G41: 1269.415
B42: Feb | C42: 114.88 | D42: 133.815 | E42: 91.175 | F42: 53.76 | G42: 393.63
...

Sheet Top5Customers
A3: Customer Name | B3: Sum of Sales
A4: Don Flintiff | B4: 278.01
A5: Nealson Cuttler | B5: 281.675
A6: Terri Farra | B6: 289.11
A7: Brenn Dundredge | B7: 307.045
A8: Allis Wilmore | B8: 317.07
A9: Grand Total | B9: 1472.91

Sheet CountryBarChart
A3: Country | B3: Sum of Sales
A4: United Kingdom | B4: 2798.505
A5: Ireland | B5: 6696.865
A6: United States | B6: 35638.885
A7: Grand Total | B7: 45134.255

Sheet Detail1
A1: Details for Sum of Sales - Country: United Kingdom
A3: Order ID | B3: Order Date | C3: Customer ID | D3: Product ID | E3: Quantity | F3: Customer Name | G3: Email | H3: Country | I3: Coffee Type | J3: Roast Type | K3: Size | L3: Unit Price | M3: Sales | N3: Coffee Type Name | O3: Roast Type Name | P3: Loyalty Card
A4: IRV-20769-219 | B4: 44119 | C4: 77131-58092-GE | D4: E-M-0.2 | E4: 3 | F4: Vidovic Antonelli | H4: United Kingdom | I4: Exc | J4: M | K4: 0.2 | L4: 4.125 | M4: 12.375 | N4: Excelsa | O4: Medium | P4: Yes
A5: GNL-98714-885 | B5: 43897 | C5: 83731-53280-YC | D5: R-M-1 | E5: 3 | F5: Adele McFayden | H5: United Kingdom | I5: Rob | J5: M | K5: 1 | L5: 9.95 | M5: 29.85 | N5: Robusta | O5: Medium | P5: Yes
A6: SGA-30059-217 | B6: 44247 | C6: 84405-83364-DG | D6: A-D-0.5 | E6: 5 | F6: Lorianne Kyneton | G6: lkynetonrf@macromedia.com | H6: United Kingdom | I6: Ara | J6: D | K6: 0.5 | L6: 5.97 | M6: 29.85 | N6: Arabica | O6: Dark | P6: Yes
A7: ORX-57454-917 | B7: 44445 | C7: 76209-39601-ZR | D7: E-D-2.5 | E7: 3 | F7: Gnni Cheeke | G7: gcheekeqc@sitemeter.com | H7: United Kingdom | I7: Exc | J7: D | K7: 2.5 | L7: 27.945 | M7: 83.835 | N7: Excelsa | O7: Dark | P7: Yes
A8: QTG-93823-843 | B8: 44573 | C8: 46859-14212-FI | D8: E-D-0.5 | E8: 3 | F8: Chloris Sorrell | G8: csorrellph@amazon.com | H8: United Kingdom | I8: Exc | J8: D | K8: 0.5 | L8: 7.29 | M8: 21.87 | N8: Excelsa | O8: Dark | P8: No
A9: QTG-93823-843 | B9: 44573 | C9: 46859-14212-FI | D9: A-M-0.5 | E9: 1 | F9: Chloris Sorrell | G9: csorrellph@amazon.com | H9: United Kingdom | I9: Ara | J9: M | K9: 0.5 | L9: 6.75 | M9: 6.75 | N9: Arabica | O9: Medium | P9: No
A10: AWP-11469-510 | B10: 43932 | C10: 76730-63769-ND | D10: E-D-1 | E10: 2 | F10: Ryann Stickler | G10: rsticklerox@printfriendly.com | H10: United Kingdom | I10: Exc | J10: D | K10: 1 | L10: 12.15 | M10: 24.3 | N10: Excelsa | O10: Dark | P10: No
A11: XED-90333-402 | B11: 43635 | C11: 28300-14355-GF | D11: E-M-0.2 | E11: 5 | F11: Patsy Vasilenko | G11: pvasilenkoos@addtoany.com | H11: United Kingdom | I11: Exc | J11: M | K11: 0.2 | L11: 4.125 | M11: 20.625 | N11: Excelsa | O11: Medium | P11: No
A12: DXA-50313-073 | B12: 43707 | C12: 19755-55847-VW | D12: E-L-1 | E12: 2 | F12: Peyter Matignon | G12: pmatignono7@harvard.edu | H12: United Kingdom | I12: Exc | J12: L | K12: 1 | L12: 14.85 | M12: 29.7 | N12: Excelsa | O12: Light | P12: Yes
A13: YOG-94666-679 | B13: 44241 | C13: 86991-53901-AT | D13: L-D-0.2 | E13: 2 | F13: Kathleen Diable | H13: United Kingdom | I13: Lib | J13: D | K13: 0.2 | L13: 3.885 | M13: 7.77 | N13: Liberica | O13: Dark | P13: Yes
A14: CLJ-23403-689 | B14: 44289 | C14: 19413-02045-CG | D14: R-L-1 | E14: 2 | F14: Jammie Cloke | H14: United Kingdom | I14: Rob | J14: L | K14: 1 | L14: 11.95 | M14: 23.9 | N14: Robusta | O14: Light | P14: No
A15: VGI-33205-360 | B15: 43545 | C15: 96762-10814-DA | D15: L-M-0.5 | E15: 6 | F15: Jereme Gippes | G15: jgippesm0@cloudflare.com | H15: United Kingdom | I15: Lib | J15: M | K15: 0.5 | L15: 8.73 | M15: 52.38 | N15: Liberica | O15: Medium | P15: Yes
A16: EJA-79176-833 | B16: 43912 | C16: 91509-62250-GN | D16: R-M-2.5 | E16: 6 | F16: Dalia Eburah | G16: deburahld@google.co.jp | H16: United Kingdom | I16: Rob | J16: M | K16: 2.5 | L16: 22.885 | M16: 137.31 | N16: Robusta | O16: Medium | P16: No
A17: ZHQ-30471-635 | B17: 43563 | C17: 40600-58915-WZ | D17: L-M-0.5 | E17: 5 | F17: Sharona Danilchik | G17: sdanilchikl6@mit.edu | H17: United Kingdom | I17: Lib | J17: M | K17: 0.5 | L17: 8.73 | M17: 43.65 | N17: Liberica | O17: Medium | P17: No
A18: BQK-38412-229 | B18: 43812 | C18: 90392-73338-BC | D18: R-L-0.2 | E18: 3 | F18: Natal Vigrass | G18: nvigrasski@ezinearticles.com | H18: United Kingdom | I18: Rob | J18: L | K18: 0.2 | L18: 3.585 | M18: 10.755 | N18: Robusta | O18: Light | P18: No
A19: CFZ-53492-600 | B19: 44634 | C19: 64896-18468-BT | D19: L-M-0.2 | E19: 1 | F19: Selle Scurrer | G19: sscurrerk9@flavors.me | H19: United Kingdom | I19: Lib | J19: M | K19: 0.2 | L19: 4.365 | M19: 4.365 | N19: Liberica | O19: Medium | P19: No
A20: CZF-40873-691 | B20: 43646 | C20: 64988-20636-XQ | D20: E-M-0.5 | E20: 2 | F20: Silas Deehan | H20: United Kingdom | I20: Exc | J20: M | K20: 0.5 | L20: 8.25 | M20: 16.5 | N20: Excelsa | O20: Medium | P20: No
A21: AHY-20324-088 | B21: 44080 | C21: 63499-24884-PP | D21: L-L-0.2 | E21: 2 | F21: Nicky Ayris | G21: nayrisix@t-online.de | H21: United Kingdom | I21: Lib | J21: L | K21: 0.2 | L21: 4.755 | M21: 9.51 | N21: Liberica | O21: Light | P21: Yes
A22: NQZ-82067-394 | B22: 44645 | C22: 72320-29738-EB | D22: R-L-2.5 | E22: 1 | F22: Adrianne Vairow | G22: avairowiv@studiopress.com | H22: United Kingdom | I22: Rob | J22: L | K22: 2.5 | L22: 27.485 | M22: 27.485 | N22: Robusta | O22: Light | P22: No
A23: ALP-37623-536 | B23: 44015 | C23: 24689-69376-XX | D23: L-L-1 | E23: 6 | F23: Charmane Denys | G23: cdenysi1@is.gd | H23: United Kingdom | I23: Lib | J23: L | K23: 1 | L23: 15.85 | M23: 95.1 | N23: Liberica | O23: Light | P23: No
A24: CKS-47815-571 | B24: 44502 | C24: 45666-86771-EH | D24: L-L-0.5 | E24: 3 | F24: Ardith Chill | G24: achillhz@epa.gov | H24: United Kingdom | I24: Lib | J24: L | K24: 0.5 | L24: 9.51 | M24: 28.53 | N24: Liberica | O24: Light | P24: Yes
A25: SBC-95710-706 | B25: 43880 | C25: 85634-61759-ND | D25: E-M-0.2 | E25: 2 | F25: Maggy Baistow | G25: mbaistowhu@i2i.jp | H25: United Kingdom | I25: Exc | J25: M | K25: 0.2 | L25: 4.125 | M25: 8.25 | N25: Excelsa | O25: Medium | P25: Yes
A26: PVU-02950-470 | B26: 44224 | C26: 01927-46702-YT | D26: E-D-1 | E26: 1 | F26: Nelie Garnson | H26: United Kingdom | I26: Exc | J26: D | K26: 1 | L26: 12.15 | M26: 12.15 | N26: Excelsa | O26: Dark | P26: No
A27: NGG-24006-937 | B27: 44271 | C27: 29102-40100-TZ | D27: E-M-2.5 | E27: 4 | F27: Linus Flippelli | G27: lflippellih4@github.io | H27: United Kingdom | I27: Exc | J27: M | K27: 2.5 | L27: 31.625 | M27: 126.5 | N27: Excelsa | O27: Medium | P27: No
A28: OKA-93124-100 | B28: 43944 | C28: 05325-97750-WP | D28: R-M-0.5 | E28: 5 | F28: Cody Verissimo | G28: cverissimogh@theglobeandmail.com | H28: United Kingdom | I28: Rob | J28: M | K28: 0.5 | L28: 5.97 | M28: 29.85 | N28: Robusta | O28: Medium | P28: Yes
A29: UMM-28497-689 | B29: 44138 | C29: 05325-97750-WP | D29: L-L-2.5 | E29: 3 | F29: Cody Verissimo | G29: cverissimogh@theglobeandmail.com | H29: United Kingdom | I29: Lib | J29: L | K29: 2.5 | L29: 36.455 | M29: 109.365 | N29: Liberica | O29: Light | P29: Yes
A30: MVI-04946-827 | B30: 44527 | C30: 62483-50867-OM | D30: E-L-1 | E30: 1 | F30: Darby Dummer | H30: United Kingdom | I30: Exc | J30: L | K30: 1 | L30: 14.85 | M30: 14.85 | N30: Excelsa | O30: Light | P30: No
A31: VQW-91903-926 | B31: 43903 | C31: 05325-97750-WP | D31: E-D-2.5 | E31: 1 | F31: Cody Verissimo | G31: cverissimogh@theglobeandmail.com | H31: United Kingdom | I31: Exc | J31: D | K31: 2.5 | L31: 27.945 | M31: 27.945 | N31: Excelsa | O31: Dark | P31: Yes
A32: ETD-58130-674 | B32: 44505 | C32: 05325-97750-WP | D32: E-M-0.5 | E32: 2 | F32: Cody Verissimo | G32: cverissimogh@theglobeandmail.com | H32: United Kingdom | I32: Exc | J32: M | K32: 0.5 | L32: 8.25 | M32: 16.5 | N32: Excelsa | O32: Medium | P32: Yes
A33: OIB-77163-890 | B33: 44190 | C33: 38972-89678-ZM | D33: E-L-0.5 | E33: 5 | F33: Carney Clemencet | G33: cclemencetg5@weather.com | H33: United Kingdom | I33: Exc | J33: L | K33: 0.5 | L33: 8.91 | M33: 44.55 | N33: Excelsa | O33: Light | P33: Yes
A34: PBT-36926-102 | B34: 44410 | C34: 19485-98072-PS | D34: L-M-1 | E34: 4 | F34: Don Flintiff | G34: dflintiffg1@e-recht24.de | H34: United Kingdom | I34: Lib | J34: M | K34: 1 | L34: 14.55 | M34: 58.2 | N34: Liberica | O34: Medium | P34: No
A35: YES-51109-625 | B35: 44592 | C35: 91895-55605-LS | D35: E-L-0.5 | E35: 4 | F35: Elizabet Aizikowitz | G35: eaizikowitzfv@virginia.edu | H35: United Kingdom | I35: Exc | J35: L | K35: 0.5 | L35: 8.91 | M35: 35.64 | N35: Excelsa | O35: Light | P35: No
A36: HMB-30634-745 | B36: 43879 | C36: 19485-98072-PS | D36: A-D-2.5 | E36: 6 | F36: Don Flintiff | G36: dflintiffg1@e-recht24.de | H36: United Kingdom | I36: Ara | J36: D | K36: 2.5 | L36: 22.885 | M36: 137.31 | N36: Arabica | O36: Dark | P36: No
A37: SPF-31673-217 | B37: 43991 | C37: 19485-98072-PS | D37: E-M-1 | E37: 6 | F37: Don Flintiff | G37: dflintiffg1@e-recht24.de | H37: United Kingdom | I37: Exc | J37: M | K37: 1 | L37: 13.75 | M37: 82.5 | N37: Excelsa | O37: Medium | P37: No
A38: GFK-52063-244 | B38: 44011 | C38: 44981-99666-XB | D38: L-L-0.5 | E38: 6 | F38: Una Welberry | G38: uwelberryy@ebay.co.uk | H38: United Kingdom | I38: Lib | J38: L | K38: 0.5 | L38: 9.51 | M38: 57.06 | N38: Liberica | O38: Light | P38: Yes
A39: VSQ-07182-513 | B39: 43669 | C39: 18366-65239-WF | D39: L-L-0.2 | E39: 6 | F39: Brendan Grece | G39: bgrecefm@naver.com | H39: United Kingdom | I39: Lib | J39: L | K39: 0.2 | L39: 4.755 | M39: 28.53 | N39: Liberica | O39: Light | P39: No
A40: NOY-99738-977 | B40: 43737 | C40: 82872-34456-LJ | D40: R-L-2.5 | E40: 2 | F40: Madelaine Sharples | H40: United Kingdom | I40: Rob | J40: L | K40: 2.5 | L40: 27.485 | M40: 54.97 | N40: Robusta | O40: Light | P40: Yes
A41: OKU-29966-417 | B41: 43761 | C41: 76192-13390-HZ | D41: E-L-0.2 | E41: 4 | F41: Granville Alberts | G41: galbertsfc@etsy.com | H41: United Kingdom | I41: Exc | J41: L | K41: 0.2 | L41: 4.455 | M41: 17.82 | N41: Excelsa | O41: Light | P41: Yes
...

Sheet orders
A1: Order ID | B1: Order Date | C1: Customer ID | D1: Product ID | E1: Quantity | F1: Customer Name | G1: Email | H1: Country | I1: Coffee Type | J1: Roast Type | K1: Size | L1: Unit Price | M1: Sales | N1: Coffee Type Name | O1: Roast Type Name | P1: Loyalty Card
A2: QEV-37451-860 | B2: 43713 | C2: 17670-51384-MA | D2: R-M-1 | E2: 2 | F2: =_xlfn.XLOOKUP(C2,customers!$A$1:$A$1001,customers!$B$1:$B$1001,,0) -> Aloisia Allner | G2: =_xlfn.XLOOKUP(C2,customers!$A$1:$A$1001,customers!$C$1:$C$1001,,0) -> aallner0@lulu.com | H2: =_xlfn.XLOOKUP(C2,customers!$A$1:$A$1001,customers!$G$1:$G$1001,,0) -> United States | I2: =INDEX(products!$A$1:$G$49, MATCH(orders!$D2,products!$A$1:$A$49,0), MATCH(I$1,products!$A$1:$G$1,0)) -> Rob | J2: =INDEX(products!$A1:$G49, MATCH(orders!$D2,products!$A$1:$A$49,0), MATCH(J1,products!$A$1:$G$1,0)) -> M | K2: =INDEX(products!$A1:$G49, MATCH(orders!$D2,products!$A$1:$A$49,0), MATCH(K1,products!$A$1:$G$1,0)) -> 1 | L2: =INDEX(products!$A1:$G49, MATCH(orders!$D2,products!$A$1:$A$49,0), MATCH(L1,products!$A$1:$G$1,0)) -> 9.95 | M2: =L2*E2 -> 19.9 | N2: =IF(I2="Rob", "Robusta", IF(I2 = "Exc", "Excelsa", IF(I2 = "Ara", "Arabica", IF(I2 = "Lib", "Liberica", "")))) -> Robusta | O2: =IF(J2 = "M", "Medium", IF(J2 = "L", "Light", IF( J2 = "D", "Dark", ""))) -> Medium | P2: =_xlfn.XLOOKUP(Orders[[#This Row],[Customer ID]],customers!$A$1:$A$1001,customers!$I$1:$I$1001,,0) -> Yes
A3: QEV-37451-860 | B3: 43713 | C3: 17670-51384-MA | D3: E-M-0.5 | E3: 5 | F3: =_xlfn.XLOOKUP(C3,customers!$A$1:$A$1001,customers!$B$1:$B$1001,,0) -> Aloisia Allner | G3: =_xlfn.XLOOKUP(C3,customers!$A$1:$A$1001,customers!$C$1:$C$1001,,0) -> aallner0@lulu.com | H3: =_xlfn.XLOOKUP(C3,customers!$A$1:$A$1001,customers!$G$1:$G$1001,,0) -> United States | I3: =INDEX(products!$A$1:$G$49, MATCH(orders!$D3,products!$A$1:$A$49,0), MATCH(I$1,products!$A$1:$G$1,0)) -> Exc | J3: =INDEX(products!$A$1:$G$49, MATCH(orders!$D3,products!$A$1:$A$49,0), MATCH(J$1,products!$A$1:$G$1,0)) -> M | K3: =INDEX(products!$A$1:$G$49, MATCH(orders!$D3,products!$A$1:$A$49,0), MATCH(K$1,products!$A$1:$G$1,0)) -> 0.5 | L3: =INDEX(products!$A$1:$G$49, MATCH(orders!$D3,products!$A$1:$A$49,0), MATCH(L$1,products!$A$1:$G$1,0)) -> 8.25 | M3: =L3*E3 -> 41.25 | N3: =IF(I3="Rob", "Robusta", IF(I3 = "Exc", "Excelsa", IF(I3 = "Ara", "Arabica", IF(I3 = "Lib", "Liberica", "")))) -> Excelsa | O3: =IF(J3 = "M", "Medium", IF(J3 = "L", "Light", IF( J3 = "D", "Dark", ""))) -> Medium | P3: =_xlfn.XLOOKUP(Orders[[#This Row],[Customer ID]],customers!$A$1:$A$1001,customers!$I$1:$I$1001,,0) -> Yes
A4: FAA-43335-268 | B4: 44364 | C4: 21125-22134-PX | D4: A-L-1 | E4: 1 | F4: =_xlfn.XLOOKUP(C4,customers!$A$1:$A$1001,customers!$B$1:$B$1001,,0) -> Jami Redholes | G4: =_xlfn.XLOOKUP(C4,customers!$A$1:$A$1001,customers!$C$1:$C$1001,,0) -> jredholes2@tmall.com | H4: =_xlfn.XLOOKUP(C4,customers!$A$1:$A$1001,customers!$G$1:$G$1001,,0) -> United States | I4: =INDEX(products!$A$1:$G$49, MATCH(orders!$D4,products!$A$1:$A$49,0), MATCH(I$1,products!$A$1:$G$1,0)) -> Ara | J4: =INDEX(products!$A$1:$G$49, MATCH(orders!$D4,products!$A$1:$A$49,0), MATCH(J$1,products!$A$1:$G$1,0)) -> L | K4: =INDEX(products!$A$1:$G$49, MATCH(orders!$D4,products!$A$1:$A$49,0), MATCH(K$1,products!$A$1:$G$1,0)) -> 1 | L4: =INDEX(products!$A$1:$G$49, MATCH(orders!$D4,products!$A$1:$A$49,0), MATCH(L$1,products!$A$1:$G$1,0)) -> 12.95 | M4: =L4*E4 -> 12.95 | N4: =IF(I4="Rob", "Robusta", IF(I4 = "Exc", "Excelsa", IF(I4 = "Ara", "Arabica", IF(I4 = "Lib", "Liberica", "")))) -> Arabica | O4: =IF(J4 = "M", "Medium", IF(J4 = "L", "Light", IF( J4 = "D", "Dark", ""))) -> Light | P4: =_xlfn.XLOOKUP(Orders[[#This Row],[Customer ID]],customers!$A$1:$A$1001,customers!$I$1:$I$1001,,0) -> Yes
A5: KAC-83089-793 | B5: 44392 | C5: 23806-46781-OU | D5: E-M-1 | E5: 2 | F5: =_xlfn.XLOOKUP(C5,customers!$A$1:$A$1001,customers!$B$1:$B$1001,,0) -> Christoffer O' Shea | G5: =IF(_xlfn.XLOOKUP(C5,customers!$A$1:$A$1001,customers!$C$1:$C$1001,,0) = 0, "", _xlfn.XLOOKUP(C5,customers!$A$1:$A$1001,customers!$C$1:$C$1001,,0)) | H5: =_xlfn.XLOOKUP(C5,customers!$A$1:$A$1001,customers!$G$1:$G$1001,,0) -> Ireland | I5: =INDEX(products!$A$1:$G$49, MATCH(orders!$D5,products!$A$1:$A$49,0), MATCH(I$1,products!$A$1:$G$1,0)) -> Exc | J5: =INDEX(products!$A$1:$G$49, MATCH(orders!$D5,products!$A$1:$A$49,0), MATCH(J$1,products!$A$1:$G$1,0)) -> M | K5: =INDEX(products!$A$1:$G$49, MATCH(orders!$D5,products!$A$1:$A$49,0), MATCH(K$1,products!$A$1:$G$1,0)) -> 1 | L5: =INDEX(products!$A$1:$G$49, MATCH(orders!$D5,products!$A$1:$A$49,0), MATCH(L$1,products!$A$1:$G$1,0)) -> 13.75 | M5: =L5*E5 -> 27.5 | N5: =IF(I5="Rob", "Robusta", IF(I5 = "Exc", "Excelsa", IF(I5 = "Ara", "Arabica", IF(I5 = "Lib", "Liberica", "")))) -> Excelsa | O5: =IF(J5 = "M", "Medium", IF(J5 = "L", "Light", IF( J5 = "D", "Dark", ""))) -> Medium | P5: =_xlfn.XLOOKUP(Orders[[#This Row],[Customer ID]],customers!$A$1:$A$1001,customers!$I$1:$I$1001,,0) -> No
A6: KAC-83089-793 | B6: 44392 | C6: 23806-46781-OU | D6: R-L-2.5 | E6: 2 | F6: =_xlfn.XLOOKUP(C6,customers!$A$1:$A$1001,customers!$B$1:$B$1001,,0) -> Christoffer O' Shea | G6: =IF(_xlfn.XLOOKUP(C6,customers!$A$1:$A$1001,customers!$C$1:$C$1001,,0) = 0, "", _xlfn.XLOOKUP(C6,customers!$A$1:$A$1001,customers!$C$1:$C$1001,,0)) | H6: =_xlfn.XLOOKUP(C6,customers!$A$1:$A$1001,customers!$G$1:$G$1001,,0) -> Ireland | I6: =INDEX(products!$A$1:$G$49, MATCH(orders!$D6,products!$A$1:$A$49,0), MATCH(I$1,products!$A$1:$G$1,0)) -> Rob | J6: =INDEX(products!$A$1:$G$49, MATCH(orders!$D6,products!$A$1:$A$49,0), MATCH(J$1,products!$A$1:$G$1,0)) -> L | K6: =INDEX(products!$A$1:$G$49, MATCH(orders!$D6,products!$A$1:$A$49,0), MATCH(K$1,products!$A$1:$G$1,0)) -> 2.5 | L6: =INDEX(products!$A$1:$G$49, MATCH(orders!$D6,products!$A$1:$A$49,0), MATCH(L$1,products!$A$1:$G$1,0)) -> 27.485 | M6: =L6*E6 -> 54.97 | N6: =IF(I6="Rob", "Robusta", IF(I6 = "Exc", "Excelsa", IF(I6 = "Ara", "Arabica", IF(I6 = "Lib", "Liberica", "")))) -> Robusta | O6: =IF(J6 = "M", "Medium", IF(J6 = "L", "Light", IF( J6 = "D", "Dark", ""))) -> Light | P6: =_xlfn.XLOOKUP(Orders[[#This Row],[Customer ID]],customers!$A$1:$A$1001,customers!$I$1:$I$1001,,0) -> No
A7: CVP-18956-553 | B7: 44412 | C7: 86561-91660-RB | D7: L-D-1 | E7: 3 | F7: =_xlfn.XLOOKUP(C7,customers!$A$1:$A$1001,customers!$B$1:$B$1001,,0) -> Beryle Cottier | G7: =IF(_xlfn.XLOOKUP(C7,customers!$A$1:$A$1001,customers!$C$1:$C$1001,,0) = 0, "", _xlfn.XLOOKUP(C7,customers!$A$1:$A$1001,customers!$C$1:$C$1001,,0)) | H7: =_xlfn.XLOOKUP(C7,customers!$A$1:$A$1001,customers!$G$1:$G$1001,,0) -> United States | I7: =INDEX(products!$A$1:$G$49, MATCH(orders!$D7,products!$A$1:$A$49,0), MATCH(I$1,products!$A$1:$G$1,0)) -> Lib | J7: =INDEX(products!$A$1:$G$49, MATCH(orders!$D7,products!$A$1:$A$49,0), MATCH(J$1,products!$A$1:$G$1,0)) -> D | K7: =INDEX(products!$A$1:$G$49, MATCH(orders!$D7,products!$A$1:$A$49,0), MATCH(K$1,products!$A$1:$G$1,0)) -> 1 | L7: =INDEX(products!$A$1:$G$49, MATCH(orders!$D7,products!$A$1:$A$49,0), MATCH(L$1,products!$A$1:$G$1,0)) -> 12.95 | M7: =L7*E7 -> 38.85 | N7: =IF(I7="Rob", "Robusta", IF(I7 = "Exc", "Excelsa", IF(I7 = "Ara", "Arabica", IF(I7 = "Lib", "Liberica", "")))) -> Liberica | O7: =IF(J7 = "M", "Medium", IF(J7 = "L", "Light", IF( J7 = "D", "Dark", ""))) -> Dark | P7: =_xlfn.XLOOKUP(Orders[[#This Row],[Customer ID]],customers!$A$1:$A$1001,customers!$I$1:$I$1001,,0) -> No
A8: IPP-31994-879 | B8: 44582 | C8: 65223-29612-CB | D8: E-D-0.5 | E8: 3 | F8: =_xlfn.XLOOKUP(C8,customers!$A$1:$A$1001,customers!$B$1:$B$1001,,0) -> Shaylynn Lobe | G8: =IF(_xlfn.XLOOKUP(C8,customers!$A$1:$A$1001,customers!$C$1:$C$1001,,0) = 0, "", _xlfn.XLOOKUP(C8,customers!$A$1:$A$1001,customers!$C$1:$C$1001,,0)) -> slobe6@nifty.com | H8: =_xlfn.XLOOKUP(C8,customers!$A$1:$A$1001,customers!$G$1:$G$1001,,0) -> United States | I8: =INDEX(products!$A$1:$G$49, MATCH(orders!$D8,products!$A$1:$A$49,0), MATCH(I$1,products!$A$1:$G$1,0)) -> Exc | J8: =INDEX(products!$A$1:$G$49, MATCH(orders!$D8,products!$A$1:$A$49,0), MATCH(J$1,products!$A$1:$G$1,0)) -> D | K8: =INDEX(products!$A$1:$G$49, MATCH(orders!$D8,products!$A$1:$A$49,0), MATCH(K$1,products!$A$1:$G$1,0)) -> 0.5 | L8: =INDEX(products!$A$1:$G$49, MATCH(orders!$D8,products!$A$1:$A$49,0), MATCH(L$1,products!$A$1:$G$1,0)) -> 7.29 | M8: =L8*E8 -> 21.87 | N8: =IF(I8="Rob", "Robusta", IF(I8 = "Exc", "Excelsa", IF(I8 = "Ara", "Arabica", IF(I8 = "Lib", "Liberica", "")))) -> Excelsa | O8: =IF(J8 = "M", "Medium", IF(J8 = "L", "Light", IF( J8 = "D", "Dark", ""))) -> Dark | P8: =_xlfn.XLOOKUP(Orders[[#This Row],[Customer ID]],customers!$A$1:$A$1001,customers!$I$1:$I$1001,,0) -> Yes
A9: SNZ-65340-705 | B9: 44701 | C9: 21134-81676-FR | D9: L-L-0.2 | E9: 1 | F9: =_xlfn.XLOOKUP(C9,customers!$A$1:$A$1001,customers!$B$1:$B$1001,,0) -> Melvin Wharfe | G9: =IF(_xlfn.XLOOKUP(C9,customers!$A$1:$A$1001,customers!$C$1:$C$1001,,0) = 0, "", _xlfn.XLOOKUP(C9,customers!$A$1:$A$1001,customers!$C$1:$C$1001,,0)) | H9: =_xlfn.XLOOKUP(C9,customers!$A$1:$A$1001,customers!$G$1:$G$1001,,0) -> Ireland | I9: =INDEX(products!$A$1:$G$49, MATCH(orders!$D9,products!$A$1:$A$49,0), MATCH(I$1,products!$A$1:$G$1,0)) -> Lib | J9: =INDEX(products!$A$1:$G$49, MATCH(orders!$D9,products!$A$1:$A$49,0), MATCH(J$1,products!$A$1:$G$1,0)) -> L | K9: =INDEX(products!$A$1:$G$49, MATCH(orders!$D9,products!$A$1:$A$49,0), MATCH(K$1,products!$A$1:$G$1,0)) -> 0.2 | L9: =INDEX(products!$A$1:$G$49, MATCH(orders!$D9,products!$A$1:$A$49,0), MATCH(L$1,products!$A$1:$G$1,0)) -> 4.755 | M9: =L9*E9 -> 4.755 | N9: =IF(I9="Rob", "Robusta", IF(I9 = "Exc", "Excelsa", IF(I9 = "Ara", "Arabica", IF(I9 = "Lib", "Liberica", "")))) -> Liberica | O9: =IF(J9 = "M", "Medium", IF(J9 = "L", "Light", IF( J9 = "D", "Dark", ""))) -> Light | P9: =_xlfn.XLOOKUP(Orders[[#This Row],[Customer ID]],customers!$A$1:$A$1001,customers!$I$1:$I$1001,,0) -> Yes
A10: EZT-46571-659 | B10: 43467 | C10: 03396-68805-ZC | D10: R-M-0.5 | E10: 3 | F10: =_xlfn.XLOOKUP(C10,customers!$A$1:$A$1001,customers!$B$1:$B$1001,,0) -> Guthrey Petracci | G10: =IF(_xlfn.XLOOKUP(C10,customers!$A$1:$A$1001,customers!$C$1:$C$1001,,0) = 0, "", _xlfn.XLOOKUP(C10,customers!$A$1:$A$1001,customers!$C$1:$C$1001,,0)) -> gpetracci8@livejournal.com | H10: =_xlfn.XLOOKUP(C10,customers!$A$1:$A$1001,customers!$G$1:$G$1001,,0) -> United States | I10: =INDEX(products!$A$1:$G$49, MATCH(orders!$D10,products!$A$1:$A$49,0), MATCH(I$1,products!$A$1:$G$1,0)) -> Rob | J10: =INDEX(products!$A$1:$G$49, MATCH(orders!$D10,products!$A$1:$A$49,0), MATCH(J$1,products!$A$1:$G$1,0)) -> M | K10: =INDEX(products!$A$1:$G$49, MATCH(orders!$D10,products!$A$1:$A$49,0), MATCH(K$1,products!$A$1:$G$1,0)) -> 0.5 | L10: =INDEX(products!$A$1:$G$49, MATCH(orders!$D10,products!$A$1:$A$49,0), MATCH(L$1,products!$A$1:$G$1,0)) -> 5.97 | M10: =L10*E10 -> 17.91 | N10: =IF(I10="Rob", "Robusta", IF(I10 = "Exc", "Excelsa", IF(I10 = "Ara", "Arabica", IF(I10 = "Lib", "Liberica", "")))) -> Robusta | O10: =IF(J10 = "M", "Medium", IF(J10 = "L", "Light", IF( J10 = "D", "Dark", ""))) -> Medium | P10: =_xlfn.XLOOKUP(Orders[[#This Row],[Customer ID]],customers!$A$1:$A$1001,customers!$I$1:$I$1001,,0) -> No
A11: NWQ-70061-912 | B11: 43713 | C11: 61021-27840-ZN | D11: R-M-0.5 | E11: 1 | F11: =_xlfn.XLOOKUP(C11,customers!$A$1:$A$1001,customers!$B$1:$B$1001,,0) -> Rodger Raven | G11: =IF(_xlfn.XLOOKUP(C11,customers!$A$1:$A$1001,customers!$C$1:$C$1001,,0) = 0, "", _xlfn.XLOOKUP(C11,customers!$A$1:$A$1001,customers!$C$1:$C$1001,,0)) -> rraven9@ed.gov | H11: =_xlfn.XLOOKUP(C11,customers!$A$1:$A$1001,customers!$G$1:$G$1001,,0) -> United States | I11: =INDEX(products!$A$1:$G$49, MATCH(orders!$D11,products!$A$1:$A$49,0), MATCH(I$1,products!$A$1:$G$1,0)) -> Rob | J11: =INDEX(products!$A$1:$G$49, MATCH(orders!$D11,products!$A$1:$A$49,0), MATCH(J$1,products!$A$1:$G$1,0)) -> M | K11: =INDEX(products!$A$1:$G$49, MATCH(orders!$D11,products!$A$1:$A$49,0), MATCH(K$1,products!$A$1:$G$1,0)) -> 0.5 | L11: =INDEX(products!$A$1:$G$49, MATCH(orders!$D11,products!$A$1:$A$49,0), MATCH(L$1,products!$A$1:$G$1,0)) -> 5.97 | M11: =L11*E11 -> 5.97 | N11: =IF(I11="Rob", "Robusta", IF(I11 = "Exc", "Excelsa", IF(I11 = "Ara", "Arabica", IF(I11 = "Lib", "Liberica", "")))) -> Robusta | O11: =IF(J11 = "M", "Medium", IF(J11 = "L", "Light", IF( J11 = "D", "Dark", ""))) -> Medium | P11: =_xlfn.XLOOKUP(Orders[[#This Row],[Customer ID]],customers!$A$1:$A$1001,customers!$I$1:$I$1001,,0) -> No
A12: BKK-47233-845 | B12: 44263 | C12: 76239-90137-UQ | D12: A-D-1 | E12: 4 | F12: =_xlfn.XLOOKUP(C12,customers!$A$1:$A$1001,customers!$B$1:$B$1001,,0) -> Ferrell Ferber | G12: =IF(_xlfn.XLOOKUP(C12,customers!$A$1:$A$1001,customers!$C$1:$C$1001,,0) = 0, "", _xlfn.XLOOKUP(C12,customers!$A$1:$A$1001,customers!$C$1:$C$1001,,0)) -> fferbera@businesswire.com | H12: =_xlfn.XLOOKUP(C12,customers!$A$1:$A$1001,customers!$G$1:$G$1001,,0) -> United States | I12: =INDEX(products!$A$1:$G$49, MATCH(orders!$D12,products!$A$1:$A$49,0), MATCH(I$1,products!$A$1:$G$1,0)) -> Ara | J12: =INDEX(products!$A$1:$G$49, MATCH(orders!$D12,products!$A$1:$A$49,0), MATCH(J$1,products!$A$1:$G$1,0)) -> D | K12: =INDEX(products!$A$1:$G$49, MATCH(orders!$D12,products!$A$1:$A$49,0), MATCH(K$1,products!$A$1:$G$1,0)) -> 1 | L12: =INDEX(products!$A$1:$G$49, MATCH(orders!$D12,products!$A$1:$A$49,0), MATCH(L$1,products!$A$1:$G$1,0)) -> 9.95 | M12: =L12*E12 -> 39.8 | N12: =IF(I12="Rob", "Robusta", IF(I12 = "Exc", "Excelsa", IF(I12 = "Ara", "Arabica", IF(I12 = "Lib", "Liberica", "")))) -> Arabica | O12: =IF(J12 = "M", "Medium", IF(J12 = "L", "Light", IF( J12 = "D", "Dark", ""))) -> Dark | P12: =_xlfn.XLOOKUP(Orders[[#This Row],[Customer ID]],customers!$A$1:$A$1001,customers!$I$1:$I$1001,,0) -> No
A13: VQR-01002-970 | B13: 44132 | C13: 49315-21985-BB | D13: E-L-2.5 | E13: 5 | F13: =_xlfn.XLOOKUP(C13,customers!$A$1:$A$1001,customers!$B$1:$B$1001,,0) -> Duky Phizackerly | G13: =IF(_xlfn.XLOOKUP(C13,customers!$A$1:$A$1001,customers!$C$1:$C$1001,,0) = 0, "", _xlfn.XLOOKUP(C13,customers!$A$1:$A$1001,customers!$C$1:$C$1001,,0)) -> dphizackerlyb@utexas.edu | H13: =_xlfn.XLOOKUP(C13,customers!$A$1:$A$1001,customers!$G$1:$G$1001,,0) -> United States | I13: =INDEX(products!$A$1:$G$49, MATCH(orders!$D13,products!$A$1:$A$49,0), MATCH(I$1,products!$A$1:$G$1,0)) -> Exc | J13: =INDEX(products!$A$1:$G$49, MATCH(orders!$D13,products!$A$1:$A$49,0), MATCH(J$1,products!$A$1:$G$1,0)) -> L | K13: =INDEX(products!$A$1:$G$49, MATCH(orders!$D13,products!$A$1:$A$49,0), MATCH(K$1,products!$A$1:$G$1,0)) -> 2.5 | L13: =INDEX(products!$A$1:$G$49, MATCH(orders!$D13,products!$A$1:$A$49,0), MATCH(L$1,products!$A$1:$G$1,0)) -> 34.155 | M13: =L13*E13 -> 170.775 | N13: =IF(I13="Rob", "Robusta", IF(I13 = "Exc", "Excelsa", IF(I13 = "Ara", "Arabica", IF(I13 = "Lib", "Liberica", "")))) -> Excelsa | O13: =IF(J13 = "M", "Medium", IF(J13 = "L", "Light", IF( J13 = "D", "Dark", ""))) -> Light | P13: =_xlfn.XLOOKUP(Orders[[#This Row],[Customer ID]],customers!$A$1:$A$1001,customers!$I$1:$I$1001,,0) -> Yes
A14: SZW-48378-399 | B14: 44744 | C14: 34136-36674-OM | D14: R-M-1 | E14: 5 | F14: =_xlfn.XLOOKUP(C14,customers!$A$1:$A$1001,customers!$B$1:$B$1001,,0) -> Rosaleen Scholar | G14: =IF(_xlfn.XLOOKUP(C14,customers!$A$1:$A$1001,customers!$C$1:$C$1001,,0) = 0, "", _xlfn.XLOOKUP(C14,customers!$A$1:$A$1001,customers!$C$1:$C$1001,,0)) -> rscholarc@nyu.edu | H14: =_xlfn.XLOOKUP(C14,customers!$A$1:$A$1001,customers!$G$1:$G$1001,,0) -> United States | I14: =INDEX(products!$A$1:$G$49, MATCH(orders!$D14,products!$A$1:$A$49,0), MATCH(I$1,products!$A$1:$G$1,0)) -> Rob | J14: =INDEX(products!$A$1:$G$49, MATCH(orders!$D14,products!$A$1:$A$49,0), MATCH(J$1,products!$A$1:$G$1,0)) -> M | K14: =INDEX(products!$A$1:$G$49, MATCH(orders!$D14,products!$A$1:$A$49,0), MATCH(K$1,products!$A$1:$G$1,0)) -> 1 | L14: =INDEX(products!$A$1:$G$49, MATCH(orders!$D14,products!$A$1:$A$49,0), MATCH(L$1,products!$A$1:$G$1,0)) -> 9.95 | M14: =L14*E14 -> 49.75 | N14: =IF(I14="Rob", "Robusta", IF(I14 = "Exc", "Excelsa", IF(I14 = "Ara", "Arabica", IF(I14 = "Lib", "Liberica", "")))) -> Robusta | O14: =IF(J14 = "M", "Medium", IF(J14 = "L", "Light", IF( J14 = "D", "Dark", ""))) -> Medium | P14: =_xlfn.XLOOKUP(Orders[[#This Row],[Customer ID]],customers!$A$1:$A$1001,customers!$I$1:$I$1001,,0) -> No
A15: ITA-87418-783 | B15: 43973 | C15: 39396-12890-PE | D15: R-D-2.5 | E15: 2 | F15: =_xlfn.XLOOKUP(C15,customers!$A$1:$A$1001,customers!$B$1:$B$1001,,0) -> Terence Vanyutin | G15: =IF(_xlfn.XLOOKUP(C15,customers!$A$1:$A$1001,customers!$C$1:$C$1001,,0) = 0, "", _xlfn.XLOOKUP(C15,customers!$A$1:$A$1001,customers!$C$1:$C$1001,,0)) -> tvanyutind@wix.com | H15: =_xlfn.XLOOKUP(C15,customers!$A$1:$A$1001,customers!$G$1:$G$1001,,0) -> United States | I15: =INDEX(products!$A$1:$G$49, MATCH(orders!$D15,products!$A$1:$A$49,0), MATCH(I$1,products!$A$1:$G$1,0)) -> Rob | J15: =INDEX(products!$A$1:$G$49, MATCH(orders!$D15,products!$A$1:$A$49,0), MATCH(J$1,products!$A$1:$G$1,0)) -> D | K15: =INDEX(products!$A$1:$G$49, MATCH(orders!$D15,products!$A$1:$A$49,0), MATCH(K$1,products!$A$1:$G$1,0)) -> 2.5 | L15: =INDEX(products!$A$1:$G$49, MATCH(orders!$D15,products!$A$1:$A$49,0), MATCH(L$1,products!$A$1:$G$1,0)) -> 20.585 | M15: =L15*E15 -> 41.17 | N15: =IF(I15="Rob", "Robusta", IF(I15 = "Exc", "Excelsa", IF(I15 = "Ara", "Arabica", IF(I15 = "Lib", "Liberica", "")))) -> Robusta | O15: =IF(J15 = "M", "Medium", IF(J15 = "L", "Light", IF( J15 = "D", "Dark", ""))) -> Dark | P15: =_xlfn.XLOOKUP(Orders[[#This Row],[Customer ID]],customers!$A$1:$A$1001,customers!$I$1:$I$1001,,0) -> No
A16: GNZ-46006-527 | B16: 44656 | C16: 95875-73336-RG | D16: L-D-0.2 | E16: 3 | F16: =_xlfn.XLOOKUP(C16,customers!$A$1:$A$1001,customers!$B$1:$B$1001,,0) -> Patrice Trobe | G16: =IF(_xlfn.XLOOKUP(C16,customers!$A$1:$A$1001,customers!$C$1:$C$1001,,0) = 0, "", _xlfn.XLOOKUP(C16,customers!$A$1:$A$1001,customers!$C$1:$C$1001,,0)) -> ptrobee@wunderground.com | H16: =_xlfn.XLOOKUP(C16,customers!$A$1:$A$1001,customers!$G$1:$G$1001,,0) -> United States | I16: =INDEX(products!$A$1:$G$49, MATCH(orders!$D16,products!$A$1:$A$49,0), MATCH(I$1,products!$A$1:$G$1,0)) -> Lib | J16: =INDEX(products!$A$1:$G$49, MATCH(orders!$D16,products!$A$1:$A$49,0), MATCH(J$1,products!$A$1:$G$1,0)) -> D | K16: =INDEX(products!$A$1:$G$49, MATCH(orders!$D16,products!$A$1:$A$49,0), MATCH(K$1,products!$A$1:$G$1,0)) -> 0.2 | L16: =INDEX(products!$A$1:$G$49, MATCH(orders!$D16,products!$A$1:$A$49,0), MATCH(L$1,products!$A$1:$G$1,0)) -> 3.885 | M16: =L16*E16 -> 11.655 | N16: =IF(I16="Rob", "Robusta", IF(I16 = "Exc", "Excelsa", IF(I16 = "Ara", "Arabica", IF(I16 = "Lib", "Liberica", "")))) -> Liberica | O16: =IF(J16 = "M", "Medium", IF(J16 = "L", "Light", IF( J16 = "D", "Dark", ""))) -> Dark | P16: =_xlfn.XLOOKUP(Orders[[#This Row],[Customer ID]],customers!$A$1:$A$1001,customers!$I$1:$I$1001,,0) -> Yes
... A1001: IRV-20769-219 | B1001: 44119 | C1001: 77131-58092-GE | D1001: E-M-0.2 | E1001: 3 | F1001: =_xlfn.XLOOKUP(C1001,customers!$A$1:$A$1001,customers!$B$1:$B$1001,,0) -> Vidovic Antonelli | G1001: =IF(_xlfn.XLOOKUP(C1001,customers!$A$1:$A$1001,customers!$C$1:$C$1001,,0) = 0, "", _xlfn.XLOOKUP(C1001,customers!$A$1:$A$1001,customers!$C$1:$C$1001,,0)) | H1001: =_xlfn.XLOOKUP(C1001,customers!$A$1:$A$1001,customers!$G$1:$G$1001,,0) -> United Kingdom | I1001: =INDEX(products!$A$1:$G$49, MATCH(orders!$D1001,products!$A$1:$A$49,0), MATCH(I$1,products!$A$1:$G$1,0)) -> Exc | J1001: =INDEX(products!$A$1:$G$49, MATCH(orders!$D1001,products!$A$1:$A$49,0), MATCH(J$1,products!$A$1:$G$1,0)) -> M | K1001: =INDEX(products!$A$1:$G$49, MATCH(orders!$D1001,products!$A$1:$A$49,0), MATCH(K$1,products!$A$1:$G$1,0)) -> 0.2 | L1001: =INDEX(products!$A$1:$G$49, MATCH(orders!$D1001,products!$A$1:$A$49,0), MATCH(L$1,products!$A$1:$G$1,0)) -> 4.125 | M1001: =L1001*E1001 -> 12.375 | N1001: =IF(I1001="Rob", "Robusta", IF(I1001 = "Exc", "Excelsa", IF(I1001 = "Ara", "Arabica", IF(I1001 = "Lib", "Liberica", "")))) -> Excelsa | O1001: =IF(J1001 = "M", "Medium", IF(J1001 = "L", "Light", IF( J1001 = "D", "Dark", ""))) -> Medium | P1001: =_xlfn.XLOOKUP(Orders[[#This Row],[Customer ID]],customers!$A$1:$A$1001,customers!$I$1:$I$1001,,0) -> Yes

Sheet customers
A1: Customer ID | B1: Customer Name | C1: Email | D1: Phone Number | E1: Address Line 1 | F1: City | G1: Country | H1: Postcode | I1: Loyalty Card
A2: 17670-51384-MA | B2: Aloisia Allner | C2: aallner0@lulu.com | D2: +1 (862) 817-0124 | E2: 57999 Pepper Wood Alley | F2: Paterson | G2: United States | H2: 7505 | I2: Yes
A3: 73342-18763-UW | B3: Piotr Bote | C3: pbote1@yelp.com | D3: +353 (913) 396-4653 | E3: 2112 Ridgeway Hill | F3: Crumlin | G3: Ireland | H3: D6W | I3: No
A4: 21125-22134-PX | B4: Jami Redholes | C4: jredholes2@tmall.com | D4: +1 (210) 986-6806 | E4: 5214 Bartillon Park | F4: San Antonio | G4: United States | H4: 78205 | I4: Yes
A5: 71253-00052-RN | B5: Dene Azema | C5: dazema3@facebook.com | D5: +1 (217) 418-0714 | E5: 27 Maywood Place | F5: Springfield | G5: United States | H5: 62711 | I5: Yes
A6: 23806-46781-OU | B6: Christoffer O' Shea | D6: +353 (698) 362-9201 | E6: 38980 Manitowish Junction | F6: Cill Airne | G6: Ireland | H6: N41 | I6: No
A7: 86561-91660-RB | B7: Beryle Cottier | D7: +1 (570) 289-7473 | E7: 2651 Stoughton Place | F7: Scranton | G7: United States | H7: 18505 | I7: No
A8: 65223-29612-CB | B8: Shaylynn Lobe | C8: slobe6@nifty.com | D8: +1 (937) 954-4541 | E8: 7005 Mariners Cove Place | F8: Dayton | G8: United States | H8: 45440 | I8: Yes
A9: 21134-81676-FR | B9: Melvin Wharfe | D9: +353 (507) 574-3034 | E9: 7 Straubel Road | F9: Kill | G9: Ireland | H9: P24 | I9: Yes
A10: 03396-68805-ZC | B10: Guthrey Petracci | C10: gpetracci8@livejournal.com | D10: +1 (310) 868-1842 | E10: 949 Paget Parkway | F10: Los Angeles | G10: United States | H10: 90045 | I10: No
A11: 61021-27840-ZN | B11: Rodger Raven | C11: rraven9@ed.gov | D11: +1 (213) 263-0288 | E11: 1 Reinke Avenue | F11: Los Angeles | G11: United States | H11: 90065 | I11: No
A12: 76239-90137-UQ | B12: Ferrell Ferber | C12: fferbera@businesswire.com | D12: +1 (408) 383-5302 | E12: 68 High Crossing Court | F12: San Jose | G12: United States | H12: 95160 | I12: No
A13: 49315-21985-BB | B13: Duky Phizackerly | C13: dphizackerlyb@utexas.edu | D13: +1 (408) 533-6012 | E13: 28643 Bluejay Crossing | F13: San Jose | G13: United States | H13: 95194 | I13: Yes
A14: 34136-36674-OM | B14: Rosaleen Scholar | C14: rscholarc@nyu.edu | D14: +1 (804) 420-0420 | E14: 80915 Montana Park | F14: Richmond | G14: United States | H14: 23285 | I14: No
A15: 39396-12890-PE | B15: Terence Vanyutin | C15: tvanyutind@wix.com | E15: 331 Bunting Hill | F15: Migrate | G15: United States | H15: 41905 | I15: No
A16: 95875-73336-RG | B16: Patrice Trobe | C16: ptrobee@wunderground.com | D16: +1 (314) 240-7896 | E16: 827 Declaration Plaza | F16: Saint Louis | G16: United States | H16: 63131 | I16: Yes
A17: 25473-43727-BY | B17: Llywellyn Oscroft | C17: loscroftf@ebay.co.uk | E17: 022 Roth Place | F17: Philadelphia | G17: United States | H17: 19172 | I17: No
A18: 99643-51048-IQ | B18: Minni Alabaster | C18: malabasterg@hexun.com | D18: +1 (971) 483-6255 | E18: 3 Charing Cross Trail | F18: Portland | G18: United States | H18: 97271 | I18: No
A19: 62173-15287-CU | B19: Rhianon Broxup | C19: rbroxuph@jimdo.com | D19: +1 (713) 663-1338 | E19: 83517 Thierer Court | F19: Houston | G19: United States | H19: 77240 | I19: No
A20: 57611-05522-ST | B20: Pall Redford | C20: predfordi@ow.ly | E20: 7337 Hayes Junction | F20: Caherconlish | G20: Ireland | H20: F45 | I20: Yes
A21: 76664-37050-DT | B21: Aurea Corradino | C21: acorradinoj@harvard.edu | D21: +1 (646) 202-5965 | E21: 698 Canary Terrace | F21: New York City | G21: United States | H21: 10060 | I21: Yes
A22: 84565-53984-SX | B22: Kendal Scardefield | D22: +353 (733) 405-3302 | E22: 3 Northridge Crossing | F22: Clondalkin | G22: Ireland | H22: D24 | I22: Yes
A23: 03090-88267-BQ | B23: Avrit Davidowsky | C23: adavidowskyl@netvibes.com | D23: +1 (616) 481-9962 | E23: 9 Warrior Junction | F23: Grand Rapids | G23: United States | H23: 49560 | I23: No
A24: 37651-47492-NC | B24: Annabel Antuk | C24: aantukm@kickstarter.com | D24: +1 (941) 740-6268 | E24: 77965 Lawn Park | F24: Punta Gorda | G24: United States | H24: 33982 | I24: Yes
A25: 95399-57205-HI | B25: Iorgo Kleinert | C25: ikleinertn@timesonline.co.uk | D25: +1 (360) 352-6598 | E25: 1 Morningstar Lane | F25: Vancouver | G25: United States | H25: 98682 | I25: Yes
A26: 24010-66714-HW | B26: Chrisy Blofeld | C26: cblofeldo@amazon.co.uk | D26: +1 (303) 936-3357 | E26: 013 Talisman Terrace | F26: Englewood | G26: United States | H26: 80150 | I26: No
A27: 07591-92789-UA | B27: Culley Farris | D27: +1 (941) 267-4822 | E27: 4 Mitchell Drive | F27: Punta Gorda | G27: United States | H27: 33982 | I27: Yes
A28: 49231-44455-IC | B28: Selene Shales | C28: sshalesq@umich.edu | D28: +1 (707) 881-5004 | E28: 74 Bultman Plaza | F28: Petaluma | G28: United States | H28: 94975 | I28: Yes
A29: 50124-88608-EO | B29: Vivie Danneil | C29: vdanneilr@mtv.com | D29: +353 (751) 346-0399 | E29: 5626 Darwin Avenue | F29: Tralee | G29: Ireland | H29: V92 | I29: No
A30: 00888-74814-UZ | B30: Theresita Newbury | C30: tnewburys@usda.gov | D30: +353 (803) 587-0026 | E30: 79526 Bultman Lane | F30: Clonskeagh | G30: Ireland | H30: D04 | I30: No
A31: 14158-30713-OB | B31: Mozelle Calcutt | C31: mcalcuttt@baidu.com | D31: +353 (928) 869-1762 | E31: 4389 Russell Way | F31: Rathwire | G31: Ireland | H31: Y25 | I31: Yes
A32: 51427-89175-QJ | B32: Adrian Swaine | D32: +1 (303) 486-9517 | E32: 95 Straubel Hill | F32: Aurora | G32: United States | H32: 80044 | I32: No
A33: 52082-49024-ON | B33: Ray Leivesley | C33: rleivesleyv@canalblog.com | D33: +1 (212) 535-7791 | E33: 91 Stephen Drive | F33: Jamaica | G33: United States | H33: 11407 | I33: No
A34: 04540-43685-DV | B34: Nelly Basezzi | C34: nbasezziw@webeden.co.uk | D34: +353 (125) 815-7345 | E34: 923 Mallard Junction | F34: Bailieborough | G34: Ireland | H34: C15 | I34: Yes
A35: 39123-12846-YJ | B35: Gallard Gatheral | C35: ggatheralx@123-reg.co.uk | E35: 40 Clemons Place | F35: Grand Forks | G35: United States | H35: 58207 | I35: No
A36: 44981-99666-XB | B36: Una Welberry | C36: uwelberryy@ebay.co.uk | D36: +44 (392) 503-8132 | E36: 40915 Schlimgen Park | F36: Upton | G36: United Kingdom | H36: DN21 | I36: Yes
A37: 24825-51803-CQ | B37: Faber Eilhart | C37: feilhartz@who.int | D37: +1 (304) 510-6095 | E37: 6966 Victoria Street | F37: Charleston | G37: United States | H37: 25362 | I37: No
A38: 77634-13918-GJ | B38: Zorina Ponting | C38: zponting10@altervista.org | D38: +1 (501) 172-1476 | E38: 7118 Holmberg Court | F38: Little Rock | G38: United States | H38: 72204 | I38: No
A39: 13694-25001-LX | B39: Silvio Strase | C39: sstrase11@booking.com | D39: +1 (303) 579-8015 | E39: 5 Forest Lane | F39: Denver | G39: United States | H39: 80291 | I39: No
A40: 08523-01791-TI | B40: Dorie de la Tremoille | C40: dde12@unesco.org | D40: +1 (612) 492-5160 | E40: 0817 Dennis Street | F40: Minneapolis | G40: United States | H40: 55458 | I40: No
...

Sheet products
A1: Product ID | B1: Coffee Type | C1: Roast Type | D1: Size | E1: Unit Price | F1: Price per 100g | G1: Profit
A2: A-L-0.2 | B2: Ara | C2: L | D2: 0.2 | E2: 3.885 | F2: 1.9425 | G2: 0.34965
A3: A-L-0.5 | B3: Ara | C3: L | D3: 0.5 | E3: 7.77 | F3: 1.554 | G3: 0.6993
A4: A-L-1 | B4: Ara | C4: L | D4: 1 | E4: 12.95 | F4: 1.295 | G4: 1.1655
A5: A-L-2.5 | B5: Ara | C5: L | D5: 2.5 | E5: 29.785 | F5: 1.1914 | G5: 2.68065
A6: A-M-0.2 | B6: Ara | C6: M | D6: 0.2 | E6: 3.375 | F6: 1.6875 | G6: 0.30375
A7: A-M-0.5 | B7: Ara | C7: M | D7: 0.5 | E7: 6.75 | F7: 1.35 | G7: 0.6075
A8: A-M-1 | B8: Ara | C8: M | D8: 1 | E8: 11.25 | F8: 1.125 | G8: 1.0125
A9: A-M-2.5 | B9: Ara | C9: M | D9: 2.5 | E9: 25.875 | F9: 1.035 | G9: 2.32875
A10: A-D-0.2 | B10: Ara | C10: D | D10: 0.2 | E10: 2.985 | F10: 1.4925 | G10: 0.26865
A11: A-D-0.5 | B11: Ara | C11: D | D11: 0.5 | E11: 5.97 | F11: 1.194 | G11: 0.5373
A12: A-D-1 | B12: Ara | C12: D | D12: 1 | E12: 9.95 | F12: 0.995 | G12: 0.8955
A13: A-D-2.5 | B13: Ara | C13: D | D13: 2.5 | E13: 22.885 | F13: 0.9154 | G13: 2.05965
... A49: E-D-2.5 | B49: Exc | C49: D | D49: 2.5 | E49: 27.945 | F49: 1.1178 | G49: 3.07395
